### Go的错误机制

与主流编程语言相比：
1. 没有异常机制
2. error类型实现error接口
3. 可以通过error.New("...")创建错误示例


```
package day13

import (
	"errors"
	"fmt"
	"testing"
)

var LessThanTwoErr = errors.New("n should not less than 2")

var LargeThan100Err = errors.New("n should not less than 2")

//斐波那契数列
func getFibonacci(n int) ([]int, error) {
	if n < 2 {
		return nil, LessThanTwoErr
	}
	if n > 100 {
		return nil, LargeThan100Err
	}
	firstList := []int{1, 1}
	for i := 2; i <= n; i++ {
		firstList = append(firstList, firstList[n-2]+firstList[n-1])
	}
	return firstList, nil
}

func TestGetFibonacci(t *testing.T) {
	if v, err := getFibonacci(-2); err != nil {
		if err == LessThanTwoErr {
			fmt.Println("less than")
		}
		if err == LargeThan100Err {
			fmt.Println("too large")
		}
	} else {
		t.Log(v)
	}
}

```

### panic
- panic用于不可恢复的错误
- panic退出前可以执行defer的内容

### panic VS os.Exit()
- os.Exit()退出不会调用defer
- os.Exit()退出时不输出当前调用栈信息

### recover 
recover在捕获了panic抛出的错误时，程序不会崩溃
```
package day13

import (
	"errors"
	"fmt"
	"testing"
)

func TestFanic(t *testing.T) {
	//出现错误也会执行
	defer func() {
		if error := recover(); error != nil {
			fmt.Println("recover from ", error)
		}
	}()
	fmt.Println("start")
	panic(errors.New("something error"))
}

//func TestExit(t *testing.T) {
//	// 不会执行
//	defer func() {
//		fmt.Println("finally")
//	}()
//	fmt.Println("start")
//	os.Exit(-1)
//}

```
